Workbook

Sheet General Parameters
A2: Semi-continuous two-stage cultivation
A4: Cells: | B4: MDCKsus ECACC | J4: Seed virus | K4: IAV PR8/8/34 H1N1 DIP depleted, adapted for MDCKsus ECACC, Xeno, P6
A5: Passage number: X | J5: MOI | K5: 0.1 | M5: Titer 0.9 E9 PFU/mL
A6: Volume CB: 90 mL | J6: Virus Input | K6: 0.014 mL | M6: Trypsin | N6: 20 U/mL
G7: =AVERAGE(Q17:Q24) -> -0.0031423154 | J7: Infection | K7: 43657.376
A10: Experimenter | G10: pH | I10: Gewicht | K10: Cells bioreactor | AD10: Virus bioreactor 3 | AX10: Virus bioreactor 3
A11: # | B11: Time | C11: Time | D11: Time | E11: Time p.i | F11: Time p.i | G11: pH off. | H11: pH off. | I11: CB | J11: VB3 | K11: Viab. Cells1 | L11: Viab. Cells2 | M11: Av. Viab. Cells | N11: Total cells1 | O11: Total cells2 | P11: Av. Total cells | Q11: µ | R11: Viability 1 | S11: Viability 2 | T11: Av. Viability | U11: Size1 | V11: Size2 | W11: Av. Size | X11: Gluc | Y11: Lac | Z11: Gln | AA11: Glu | AB11: NH4+ | AC11: µset | AD11: Viab. Cells1 | AE11: Viab. Cells2 | AF11: Av. Viab. Cells | AG11: Total cells1 | AH11: Total cells2 | AI11: Av. Total cells | AJ11: Viability 1 | AK11: Viability 2 | AL11: Av. Viability | AM11: Size1 | AN11: Size2 | AO11: Av. Size | AP11: Gluc | AQ11: Lac | AR11: Gln | AS11: Glu | AT11: NH4+ | AU11: Comment | AV11: # | AW11: Time p.i | AX11: HA | AY11: HA titer | AZ11: Plaque Assay | BA11: TCID50 | BB11: vRNA | BC11: Plaque*Vharvest
A12: Unit -> | B12: (d.m.y h:m) | C12: h | D12: d | E12: h | F12: d | G12: CB | H12: VB3 | I12: g | J12: g | K12: x106 c/mL | L12: x106 c/mL | M12: x106 c/mL | N12: x106 c/mL | O12: x106 c/mL | P12: x106 c/mL | Q12: h-1 | R12: % | S12: % | T12: % | U12: mm | V12: mm | W12: mm | X12: mmol/L | Y12: mmol/L | Z12: mmol/L | AA12: mmol/L | AB12: mmol/L | AC12: h-1 | AD12: x106 c/mL | AE12: x106 c/mL | AF12: x106 c/mL | AG12: x106 c/mL | AH12: x106 c/mL | AI12: x106 c/mL | AJ12: % | AK12: % | AL12: % | AM12: mm | AN12: mm | AO12: mm | AP12: mmol/L | AQ12: mmol/L | AR12: mmol/L | AS12: mmol/L | AT12: mmol/L | AV12: Unit -> | AW12: d | AX12: log10(HA Units/100µL) | AY12: virions/mL | AZ12: PFU/mL | BA12: TCID50/mL | BB12: copies/mL | BC12: PFU
A13: PN0 | B13: 43653.787 | C13: 0 | D13: =C13/24 -> 0 | E13: =(B13-$K$7)*24 -> -86.133333 | F13: =E13/24 -> -3.5888889 | G13: 7.69 | H13: 7.73 | I13: 147.07 | J13: 133.56 | K13: 0.54 | L13: 0.55 | M13: =AVERAGE(K13:L13) -> 0.545 | N13: 0.58 | O13: 0.58 | P13: =AVERAGE(N13:O13) -> 0.58 | Q13: =(LN(M13)-LN(M12))/(C13-C12) -> #VALUE! | R13: 93.2 | S13: 93.9 | T13: =AVERAGE(R13:S13) -> 93.55 | U13: 15.34 | V13: 15.23 | W13: =AVERAGE(U13:V13) -> 15.285 | AD13: 0.62 | AE13: 0.6 | AF13: =AVERAGE(AD13:AE13) -> 0.61 | AG13: 0.65 | AH13: 0.62 | AI13: =AVERAGE(AG13:AH13) -> 0.635 | AJ13: 95.8 | AK13: 96.3 | AL13: =AVERAGE(AJ13:AK13) -> 96.05 | AM13: 15.27 | AN13: 15.4 | AO13: =AVERAGE(AM13:AN13) -> 15.335 | AV13: =A13 -> PN0 | AW13: =F13 -> -3.5888889
A14: PN1 | B14: 43654.802 | C14: =(B14-B13)*24+C13 -> 24.35 | D14: =C14/24 -> 1.0145833 | E14: =(B14-$K$7)*24 -> -61.783333 | F14: =E14/24 -> -2.5743056 | G14: 7.63 | H14: 7.65 | I14: 142.7 | J14: 128.74 | K14: 1.35 | L14: 1.3 | M14: =AVERAGE(K14:L14) -> 1.325 | N14: 1.42 | O14: 1.36 | P14: =AVERAGE(N14:O14) -> 1.39 | Q14: =(LN(M14)-LN(M13))/(C14-C13) -> 0.036483858 | R14: 94.7 | S14: 95.5 | T14: =AVERAGE(R14:S14) -> 95.1 | U14: 15.46 | V14: 15.52 | W14: =AVERAGE(U14:V14) -> 15.49 | AD14: 1.39 | AF14: =AVERAGE(AD14:AE14) -> 1.39 | AG14: 1.46 | AI14: =AVERAGE(AG14:AH14) -> 1.46 | AJ14: 95 | AL14: =AVERAGE(AJ14:AK14) -> 95 | AM14: 15.59 | AO14: =AVERAGE(AM14:AN14) -> 15.59 | AV14: =A14 -> PN1 | AW14: =F14 -> -2.5743056
A15: PN2 | B15: 43655.349 | C15: =(B15-B14)*24+C14 -> 37.466667 | D15: =C15/24 -> 1.5611111 | E15: =(B15-$K$7)*24 -> -48.666667 | F15: =E15/24 -> -2.0277778 | G15: 7.59 | H15: 7.58 | I15: 145.76 | J15: 132.55 | K15: 2.13 | L15: 2.03 | M15: =AVERAGE(K15:L15) -> 2.08 | N15: 2.24 | O15: 2.12 | P15: =AVERAGE(N15:O15) -> 2.18 | Q15: =(LN(M15)-LN(M14))/(C15-C14) -> 0.034380338 | R15: 95.3 | S15: 95.8 | T15: =AVERAGE(R15:S15) -> 95.55 | U15: 15.58 | V15: 15.65 | W15: =AVERAGE(U15:V15) -> 15.615 | AD15: 2.02 | AE15: 2.14 | AF15: =AVERAGE(AD15:AE15) -> 2.08 | AG15: 2.11 | AH15: 2.23 | AI15: =AVERAGE(AG15:AH15) -> 2.17 | AJ15: 95.7 | AK15: 95.9 | AL15: =AVERAGE(AJ15:AK15) -> 95.8 | AM15: 15.57 | AN15: 15.54 | AO15: =AVERAGE(AM15:AN15) -> 15.555 | AV15: =A15 -> PN2 | AW15: =F15 -> -2.0277778
A16: PN3 | B16: 43655.812 | C16: =(B16-B15)*24+C15 -> 48.6 | D16: =C16/24 -> 2.025 | E16: =(B16-$K$7)*24 -> -37.533333 | F16: =E16/24 -> -1.5638889 | G16: 7.42 | H16: 7.46 | I16: 145.99 | J16: 132.53 | K16: 3.16 | L16: 2.9 | M16: =AVERAGE(K16:L16) -> 3.03 | N16: 3.34 | O16: 3.07 | P16: =AVERAGE(N16:O16) -> 3.205 | Q16: =(LN(M16)-LN(M15))/(C16-C15) -> 0.033789945 | R16: 94.5 | S16: 94.6 | T16: =AVERAGE(R16:S16) -> 94.55 | U16: 15.46 | V16: 15.56 | W16: =AVERAGE(U16:V16) -> 15.51 | AD16: 2.91 | AE16: 2.92 | AF16: =AVERAGE(AD16:AE16) -> 2.915 | AG16: 3.03 | AH16: 3.05 | AI16: =AVERAGE(AG16:AH16) -> 3.04 | AJ16: 95.9 | AK16: 95.7 | AL16: =AVERAGE(AJ16:AK16) -> 95.8 | AM16: 16.06 | AN16: 16.02 | AO16: =AVERAGE(AM16:AN16) -> 16.04 | AV16: =A16 -> PN3 | AW16: =F16 -> -1.5638889
A17: PN4 | B17: 43656.36 | C17: =(B17-B16)*24+C16 -> 61.75 | D17: =C17/24 -> 2.5729167 | E17: =(B17-$K$7)*24 -> -24.383333 | F17: =E17/24 -> -1.0159722 | G17: 7.44 | H17: 7.5 | I17: 145.23 | J17: 134.79 | K17: 3.1 | L17: 3.1 | M17: =AVERAGE(K17:L17) -> 3.1 | N17: 3.29 | O17: 3.28 | P17: =AVERAGE(N17:O17) -> 3.285 | Q17: =(LN(M17)-LN(M16))/(C17-C16) -> 0.0017368435 | R17: 94.2 | S17: 94.6 | T17: =AVERAGE(R17:S17) -> 94.4 | U17: 15.4 | V17: 15.38 | W17: =AVERAGE(U17:V17) -> 15.39 | AD17: 2.3 | AE17: 2.41 | AF17: =AVERAGE(AD17:AE17) -> 2.355 | AG17: 2.46 | AH17: 2.54 | AI17: =AVERAGE(AG17:AH17) -> 2.5 | AJ17: 93.7 | AK17: 95 | AL17: =AVERAGE(AJ17:AK17) -> 94.35 | AM17: 15.57 | AN17: 15.58 | AO17: =AVERAGE(AM17:AN17) -> 15.575 | AV17: =A17 -> PN4 | AW17: =F17 -> -1.0159722
A18: PN5 | B18: 43656.878 | C18: =(B18-B17)*24+C17 -> 74.166667 | D18: =C18/24 -> 3.0902778 | E18: =(B18-$K$7)*24 -> -11.966667 | F18: =E18/24 -> -0.49861111 | I18: 144.99 | J18: 134.7 | K18: 3.19 | L18: 3.28 | M18: =AVERAGE(K18:L18) -> 3.235 | N18: 3.37 | O18: 3.46 | P18: =AVERAGE(N18:O18) -> 3.415 | Q18: =(LN(M18)-LN(M17))/(C18-C17) -> 0.0034330322 | R18: 94.7 | S18: 94.7 | T18: =AVERAGE(R18:S18) -> 94.7 | U18: 15.55 | V18: 15.52 | W18: =AVERAGE(U18:V18) -> 15.535 | AD18: 2.39 | AE18: 2.38 | AF18: =AVERAGE(AD18:AE18) -> 2.385 | AG18: 2.51 | AH18: 2.54 | AI18: =AVERAGE(AG18:AH18) -> 2.525 | AJ18: 95.1 | AK18: 94 | AL18: =AVERAGE(AJ18:AK18) -> 94.55 | AM18: 15.62 | AN18: 15.67 | AO18: =AVERAGE(AM18:AN18) -> 15.645 | AV18: =A18 -> PN5 | AW18: =F18 -> -0.49861111
A19: PN6 | B19: 43657.361 | C19: =(B19-B18)*24+C18 -> 85.766667 | D19: =C19/24 -> 3.5736111 | E19: =(B19-$K$7)*24 -> -0.36666667 | F19: =E19/24 -> -0.015277778 | I19: 145.09 | J19: 134.6 | K19: 2.99 | L19: 2.86 | M19: =AVERAGE(K19:L19) -> 2.925 | N19: 3.15 | O19: 3.03 | P19: =AVERAGE(N19:O19) -> 3.09 | Q19: =(LN(M19)-LN(M18))/(C19-C18) -> -0.0086840041 | R19: 94.9 | S19: 94.5 | T19: =AVERAGE(R19:S19) -> 94.7 | U19: 15.56 | V19: 15.67 | W19: =AVERAGE(U19:V19) -> 15.615 | AD19: 2.55 | AE19: 2.44 | AF19: =AVERAGE(AD19:AE19) -> 2.495 | AG19: 2.68 | AH19: 2.57 | AI19: =AVERAGE(AG19:AH19) -> 2.625 | AJ19: 94.9 | AK19: 95 | AL19: =AVERAGE(AJ19:AK19) -> 94.95 | AM19: 15.64 | AN19: 15.85 | AO19: =AVERAGE(AM19:AN19) -> 15.745 | AU19: Infection 9:02 | AV19: =A19 -> PN6 | AW19: =F19 -> -0.015277778 | AX19: 0 | AZ19: 280000 | BA19: 240000 | BB19: 12741057
A20: PN7 | B20: 43657.873 | C20: =(B20-B19)*24+C19 -> 98.05 | D20: =C20/24 -> 4.0854167 | E20: =(B20-$K$7)*24 -> 11.916667 | F20: =E20/24 -> 0.49652778 | H20: 7.55 | I20: 141.64 | J20: 132.47 | K20: 2.69 | M20: =AVERAGE(K20:L20) -> 2.69 | N20: 2.89 | P20: =AVERAGE(N20:O20) -> 2.89 | Q20: =(LN(M20)-LN(M19))/(C20-C19) -> -0.0068184494 | R20: 93.1 | T20: =AVERAGE(R20:S20) -> 93.1 | U20: 15.56 | W20: =AVERAGE(U20:V20) -> 15.56 | AD20: 1.83 | AE20: 1.78 | AF20: =AVERAGE(AD20:AE20) -> 1.805 | AG20: 1.93 | AH20: 1.93 | AI20: =AVERAGE(AG20:AH20) -> 1.93 | AJ20: 94.6 | AK20: 92.4 | AL20: =AVERAGE(AJ20:AK20) -> 93.5 | AM20: 14.33 | AN20: 14.51 | AO20: =AVERAGE(AM20:AN20) -> 14.42 | AV20: =A20 -> PN7 | AW20: =F20 -> 0.49652778 | AX20: 2.8482106 | AZ20: 280000000 | BA20: 560000000 | BB20: 3.9537183e+10
A21: PN8 | B21: 43658.365 | C21: =(B21-B20)*24+C20 -> 109.86667 | D21: =C21/24 -> 4.5777778 | E21: =(B21-$K$7)*24 -> 23.733333 | F21: =E21/24 -> 0.98888889 | G21: 7.48 | H21: 7.55 | I21: 145.64 | J21: 132.2 | K21: 2.66 | L21: 2.68 | M21: =AVERAGE(K21:L21) -> 2.67 | N21: 2.84 | O21: 2.83 | P21: =AVERAGE(N21:O21) -> 2.835 | Q21: =(LN(M21)-LN(M20))/(C21-C20) -> -0.00063154199 | R21: 93.5 | S21: 94.6 | T21: =AVERAGE(R21:S21) -> 94.05 | U21: 15.69 | V21: 15.85 | W21: =AVERAGE(U21:V21) -> 15.77 | AD21: 0.59 | AE21: 0.57 | AF21: =AVERAGE(AD21:AE21) -> 0.58 | AG21: 0.66 | AH21: 0.65 | AI21: =AVERAGE(AG21:AH21) -> 0.655 | AJ21: 88.1 | AK21: 87.3 | AL21: =AVERAGE(AJ21:AK21) -> 87.7 | AM21: 13.56 | AN21: 13.7 | AO21: =AVERAGE(AM21:AN21) -> 13.63 | AV21: =A21 -> PN8 | AW21: =F21 -> 0.98888889 | AX21: 3.0285543 | AZ21: 28000000 | BA21: 56000000 | BB21: 7.740283e+10
A22: PN9 | B22: 43658.773 | C22: =(B22-B21)*24+C21 -> 119.65 | D22: =C22/24 -> 4.9854167 | E22: =(B22-$K$7)*24 -> 33.516667 | F22: =E22/24 -> 1.3965278 | I22: 146.03 | J22: 127.6 | K22: 2.49 | L22: 2.29 | M22: =AVERAGE(K22:L22) -> 2.39 | N22: 2.64 | O22: 2.44 | P22: =AVERAGE(N22:O22) -> 2.54 | Q22: =(LN(M22)-LN(M21))/(C22-C21) -> -0.011323861 | R22: 94.1 | S22: 94.1 | T22: =AVERAGE(R22:S22) -> 94.1 | U22: 15.69 | V22: 16.04 | W22: =AVERAGE(U22:V22) -> 15.865 | AD22: 0.84 | AE22: 0.89 | AF22: =AVERAGE(AD22:AE22) -> 0.865 | AG22: 0.9 | AH22: 0.94 | AI22: =AVERAGE(AG22:AH22) -> 0.92 | AJ22: 93.7 | AK22: 94 | AL22: =AVERAGE(AJ22:AK22) -> 93.85 | AM22: 14.78 | AN22: 14.49 | AO22: =AVERAGE(AM22:AN22) -> 14.635 | AV22: =A22 -> PN9 | AW22: =F22 -> 1.3965278 | AX22: 2.9437715 | AZ22: 4000000 | BA22: 18000000 | BB22: 5.2648237e+10
A23: PN10 | B23: 43659.397 | C23: =(B23-B22)*24+C22 -> 134.61667 | D23: =C23/24 -> 5.6090278 | E23: =(B23-$K$7)*24 -> 48.483333 | F23: =E23/24 -> 2.0201389 | H23: 7.53 | I23: 144.55 | J23: 131.68 | K23: 3.03 | L23: 2.83 | M23: =AVERAGE(K23:L23) -> 2.93 | N23: 3.2 | O23: 2.97 | P23: =AVERAGE(N23:O23) -> 3.085 | Q23: =(LN(M23)-LN(M22))/(C23-C22) -> 0.01361085 | R23: 94.7 | S23: 95.3 | T23: =AVERAGE(R23:S23) -> 95 | U23: 15.78 | V23: 15.92 | W23: =AVERAGE(U23:V23) -> 15.85 | AD23: 0.26 | AE23: 0.27 | AF23: =AVERAGE(AD23:AE23) -> 0.265 | AG23: 0.3 | AH23: 0.31 | AI23: =AVERAGE(AG23:AH23) -> 0.305 | AJ23: 87.4 | AK23: 86.2 | AL23: =AVERAGE(AJ23:AK23) -> 86.8 | AM23: 12.81 | AN23: 12.42 | AO23: =AVERAGE(AM23:AN23) -> 12.615 | AV23: =A23 -> PN10 | AW23: =F23 -> 2.0201389 | AX23: 3.2873826 | AZ23: 120000 | BA23: 560000 | BB23: 3.4081081e+10
A24: PN11 | B24: 43659.87 | C24: =(B24-B23)*24+C23 -> 145.98333 | D24: =C24/24 -> 6.0826389 | E24: =(B24-$K$7)*24 -> 59.85 | F24: =E24/24 -> 2.49375 | I24: 144.42 | J24: 132.32 | K24: 2.44 | L24: 2.42 | M24: =AVERAGE(K24:L24) -> 2.43 | N24: 2.59 | O24: 2.54 | P24: =AVERAGE(N24:O24) -> 2.565 | Q24: =(LN(M24)-LN(M23))/(C24-C23) -> -0.016461393 | R24: 94.2 | S24: 95.1 | T24: =AVERAGE(R24:S24) -> 94.65 | U24: 15.78 | V24: 15.85 | W24: =AVERAGE(U24:V24) -> 15.815 | AD24: 1.38 | AE24: 1.38 | AF24: =AVERAGE(AD24:AE24) -> 1.38 | AG24: 1.42 | AH24: 1.43 | AI24: =AVERAGE(AG24:AH24) -> 1.425 | AJ24: 96.9 | AK24: 96.4 | AL24: =AVERAGE(AJ24:AK24) -> 96.65 | AM24: 14.2 | AN24: 14.3 | AO24: =AVERAGE(AM24:AN24) -> 14.25 | AV24: =A24 -> PN11 | AW24: =F24 -> 2.49375 | AX24: 2.7652954 | AZ24: 12000 | BA24: 130000 | BB24: 1.0536993e+10
A25: PN12 | B25: 43660.329 | C25: =(B25-B24)*24+C24 -> 157 | D25: =C25/24 -> 6.5416667 | E25: =(B25-$K$7)*24 -> 70.866667 | F25: =E25/24 -> 2.9527778 | G25: 7.54 | H25: 7.51 | I25: 147.75 | J25: 131.23 | K25: 2.23 | L25: 2.28 | M25: =AVERAGE(K25:L25) -> 2.255 | N25: 2.36 | O25: 2.45 | P25: =AVERAGE(N25:O25) -> 2.405 | Q25: =(LN(M25)-LN(M24))/(C25-C24) -> -0.0067843828 | R25: 94.2 | S25: 93 | T25: =AVERAGE(R25:S25) -> 93.6 | U25: 15.84 | V25: 15.93 | W25: =AVERAGE(U25:V25) -> 15.885 | AD25: 0.96 | AE25: 0.94 | AF25: =AVERAGE(AD25:AE25) -> 0.95 | AG25: 1.03 | AH25: 1 | AI25: =AVERAGE(AG25:AH25) -> 1.015 | AJ25: 93.5 | AK25: 94.7 | AL25: =AVERAGE(AJ25:AK25) -> 94.1 | AM25: 15.16 | AN25: 15.15 | AO25: =AVERAGE(AM25:AN25) -> 15.155 | AV25: =A25 -> PN12 | AW25: =F25 -> 2.9527778 | AX25: 2.5828286 | AZ25: 600 | BA25: 24000 | BB25: 3.1557325e+09
A26: PN13 | B26: 43660.836 | C26: =(B26-B25)*24+C25 -> 169.16667 | D26: =C26/24 -> 7.0486111 | E26: =(B26-$K$7)*24 -> 83.033333 | F26: =E26/24 -> 3.4597222 | I26: 148.76 | J26: 131.51 | K26: 2.41 | L26: 2.41 | M26: =AVERAGE(K26:L26) -> 2.41 | N26: 2.66 | O26: 2.6 | P26: =AVERAGE(N26:O26) -> 2.63 | Q26: =(LN(M26)-LN(M25))/(C26-C25) -> 0.0054638445 | R26: 90.7 | S26: 92.6 | T26: =AVERAGE(R26:S26) -> 91.65 | U26: 15.81 | V26: 15.76 | W26: =AVERAGE(U26:V26) -> 15.785 | AD26: 0.97 | AE26: 1 | AF26: =AVERAGE(AD26:AE26) -> 0.985 | AG26: 1.02 | AH26: 1.06 | AI26: =AVERAGE(AG26:AH26) -> 1.04 | AJ26: 94.7 | AK26: 94.3 | AL26: =AVERAGE(AJ26:AK26) -> 94.5 | AM26: 15.65 | AN26: 15.6 | AO26: =AVERAGE(AM26:AN26) -> 15.625 | AV26: =A26 -> PN13 | AW26: =F26 -> 3.4597222 | AX26: 2.249314 | AZ26: 120 | BA26: 3200 | BB26: 2.2714108e+09
A27: PN14 | B27: 43661.38 | C27: =(B27-B26)*24+C26 -> 182.21667 | D27: =C27/24 -> 7.5923611 | E27: =(B27-$K$7)*24 -> 96.083333 | F27: =E27/24 -> 4.0034722 | G27: 7.49 | H27: 7.48 | I27: 148.69 | J27: 132.91 | K27: 2.83 | L27: 2.57 | M27: =AVERAGE(K27:L27) -> 2.7 | N27: 2.97 | O27: 2.71 | P27: =AVERAGE(N27:O27) -> 2.84 | Q27: =(LN(M27)-LN(M26))/(C27-C26) -> 0.0087068985 | R27: 95.3 | S27: 95.1 | T27: =AVERAGE(R27:S27) -> 95.2 | U27: 15.77 | V27: 15.86 | W27: =AVERAGE(U27:V27) -> 15.815 | AD27: 1.55 | AE27: 1.55 | AF27: =AVERAGE(AD27:AE27) -> 1.55 | AG27: 1.63 | AH27: 1.62 | AI27: =AVERAGE(AG27:AH27) -> 1.625 | AJ27: 95.3 | AK27: 96.2 | AL27: =AVERAGE(AJ27:AK27) -> 95.75 | AM27: 16.21 | AN27: 16.16 | AO27: =AVERAGE(AM27:AN27) -> 16.185 | AV27: =A27 -> PN14 | AW27: =F27 -> 4.0034722 | AX27: 0 | AZ27: 4 | BA27: 42 | BB27: 9.0265498e+08
A28: PN15 | B28: 43661.847 | C28: =(B28-B27)*24+C27 -> 193.41667 | D28: =C28/24 -> 8.0590278 | E28: =(B28-$K$7)*24 -> 107.28333 | F28: =E28/24 -> 4.4701389 | I28: 148.62 | J28: 131.88 | K28: 2.08 | L28: 2.33 | M28: =AVERAGE(K28:L28) -> 2.205 | N28: 2.23 | O28: 2.47 | P28: =AVERAGE(N28:O28) -> 2.35 | Q28: =(LN(M28)-LN(M27))/(C28-C27) -> -0.018082524 | R28: 93.1 | S28: 94.4 | T28: =AVERAGE(R28:S28) -> 93.75 | U28: 16.2 | V28: 15.92 | W28: =AVERAGE(U28:V28) -> 16.06 | AD28: 1.57 | AE28: 1.65 | AF28: =AVERAGE(AD28:AE28) -> 1.61 | AG28: 1.69 | AH28: 1.77 | AI28: =AVERAGE(AG28:AH28) -> 1.73 | AJ28: 93.1 | AK28: 93.1 | AL28: =AVERAGE(AJ28:AK28) -> 93.1 | AM28: 15.66 | AN28: 15.72 | AO28: =AVERAGE(AM28:AN28) -> 15.69 | AV28: =A28 -> PN15 | AW28: =F28 -> 4.4701389 | AX28: 0 | AZ28: 4000 | BA28: 7600 | BB28: 3.690049e+08
A29: PN16 | B29: 43662.381 | C29: =(B29-B28)*24+C28 -> 206.25 | D29: =C29/24 -> 8.59375 | E29: =(B29-$K$7)*24 -> 120.11667 | F29: =E29/24 -> 5.0048611 | G29: 7.49 | H29: 7.44 | I29: 150.57 | J29: 132.22 | K29: 2.44 | L29: 2.53 | M29: =AVERAGE(K29:L29) -> 2.485 | N29: 2.6 | O29: 2.68 | P29: =AVERAGE(N29:O29) -> 2.64 | Q29: =(LN(M29)-LN(M28))/(C29-C28) -> 0.0093152065 | R29: 93.9 | S29: 94.3 | T29: =AVERAGE(R29:S29) -> 94.1 | U29: 15.98 | V29: 15.81 | W29: =AVERAGE(U29:V29) -> 15.895 | AD29: 2.08 | AE29: 2.11 | AF29: =AVERAGE(AD29:AE29) -> 2.095 | AG29: 2.27 | AH29: 2.33 | AI29: =AVERAGE(AG29:AH29) -> 2.3 | AJ29: 91.6 | AK29: 90.5 | AL29: =AVERAGE(AJ29:AK29) -> 91.05 | AM29: 15.68 | AN29: 15.1 | AO29: =AVERAGE(AM29:AN29) -> 15.39 | AV29: =A29 -> PN16 | AW29: =F29 -> 5.0048611 | AX29: 3.031926 | AZ29: 80000000 | BA29: 32000000 | BB29: 2.7860444e+10
A30: PN17 | B30: 43662.852 | C30: =(B30-B29)*24+C29 -> 217.55 | D30: =C30/24 -> 9.0645833 | E30: =(B30-$K$7)*24 -> 131.41667 | F30: =E30/24 -> 5.4756944 | I30: 147.05 | J30: 131.53 | K30: 2.57 | L30: 2.55 | M30: =AVERAGE(K30:L30) -> 2.56 | N30: 2.73 | O30: 2.7 | P30: =AVERAGE(N30:O30) -> 2.715 | Q30: =(LN(M30)-LN(M29))/(C30-C29) -> 0.0026313804 | R30: 94.2 | S30: 94.4 | T30: =AVERAGE(R30:S30) -> 94.3 | U30: 15.81 | V30: 15.83 | W30: =AVERAGE(U30:V30) -> 15.82 | AD30: 0.76 | AE30: 0.77 | AF30: =AVERAGE(AD30:AE30) -> 0.765 | AG30: 0.82 | AH30: 0.83 | AI30: =AVERAGE(AG30:AH30) -> 0.825 | AJ30: 92.4 | AK30: 92.5 | AL30: =AVERAGE(AJ30:AK30) -> 92.45 | AM30: 13.53 | AN30: 13.31 | AO30: =AVERAGE(AM30:AN30) -> 13.42 | AV30: =A30 -> PN17 | AW30: =F30 -> 5.4756944 | AX30: 3.0776465 | AZ30: 1200000 | BA30: 5600000 | BB30: 3.6064663e+10
A31: PN18 | B31: 43663.369 | C31: =(B31-B30)*24+C30 -> 229.96667 | D31: =C31/24 -> 9.5819444 | E31: =(B31-$K$7)*24 -> 143.83333 | F31: =E31/24 -> 5.9930556 | G31: 7.42 | H31: 7.5 | I31: 145.85 | J31: 132.02 | K31: 2.86 | L31: 2.73 | M31: =AVERAGE(K31:L31) -> 2.795 | N31: 3.06 | O31: 2.88 | P31: =AVERAGE(N31:O31) -> 2.97 | Q31: =(LN(M31)-LN(M30))/(C31-C30) -> 0.0070731421 | R31: 93.5 | S31: 94.7 | T31: =AVERAGE(R31:S31) -> 94.1 | U31: 15.82 | V31: 15.92 | W31: =AVERAGE(U31:V31) -> 15.87 | AD31: 0.38 | AE31: 0.35 | AF31: =AVERAGE(AD31:AE31) -> 0.365 | AG31: 0.43 | AH31: 0.38 | AI31: =AVERAGE(AG31:AH31) -> 0.405 | AJ31: 89.9 | AK31: 91.4 | AL31: =AVERAGE(AJ31:AK31) -> 90.65 | AM31: 13.04 | AN31: 12.95 | AO31: =AVERAGE(AM31:AN31) -> 12.995 | AV31: =A31 -> PN18 | AW31: =F31 -> 5.9930556 | AX31: 2.4665642 | AZ31: 4000 | BA31: 760000 | BB31: 1.1032618e+10
A32: PN19 | B32: 43663.866 | C32: =(B32-B31)*24+C31 -> 241.88333 | D32: =C32/24 -> 10.078472 | E32: =(B32-$K$7)*24 -> 155.75 | F32: =E32/24 -> 6.4895833 | I32: 146.99 | J32: 132.17 | K32: 2.56 | L32: 2.65 | M32: =AVERAGE(K32:L32) -> 2.605 | N32: 2.73 | O32: 2.81 | P32: =AVERAGE(N32:O32) -> 2.77 | Q32: =(LN(M32)-LN(M31))/(C32-C31) -> -0.0059076446 | R32: 93.8 | S32: 94.3 | T32: =AVERAGE(R32:S32) -> 94.05 | U32: 15.9 | V32: 15.92 | W32: =AVERAGE(U32:V32) -> 15.91 | AD32: 0.73 | AE32: 0.73 | AF32: =AVERAGE(AD32:AE32) -> 0.73 | AG32: 0.79 | AH32: 0.79 | AI32: =AVERAGE(AG32:AH32) -> 0.79 | AJ32: 92 | AK32: 92.6 | AL32: =AVERAGE(AJ32:AK32) -> 92.3 | AM32: 13.53 | AN32: 13.51 | AO32: =AVERAGE(AM32:AN32) -> 13.52 | AV32: =A32 -> PN19 | AW32: =F32 -> 6.4895833 | AX32: 2.2444681 | AZ32: <E-2 | BA32: 1300000 | BB32: 7.2691861e+09
A33: PN20 | B33: 43664.34 | C33: =(B33-B32)*24+C32 -> 253.26667 | D33: =C33/24 -> 10.552778 | E33: =(B33-$K$7)*24 -> 167.13333 | F33: =E33/24 -> 6.9638889 | G33: 7.42 | H33: 7.46 | I33: 145.19 | J33: 132.28 | K33: 2.66 | L33: 2.65 | M33: =AVERAGE(K33:L33) -> 2.655 | N33: 2.83 | O33: 2.79 | P33: =AVERAGE(N33:O33) -> 2.81 | Q33: =(LN(M33)-LN(M32))/(C33-C32) -> 0.0016701593 | R33: 94.1 | S33: 94.8 | T33: =AVERAGE(R33:S33) -> 94.45 | U33: 15.91 | V33: 16.01 | W33: =AVERAGE(U33:V33) -> 15.96 | AD33: 0.88 | AE33: 0.9 | AF33: =AVERAGE(AD33:AE33) -> 0.89 | AG33: 0.93 | AH33: 0.94 | AI33: =AVERAGE(AG33:AH33) -> 0.935 | AJ33: 94.7 | AK33: 95 | AL33: =AVERAGE(AJ33:AK33) -> 94.85 | AM33: 14.14 | AN33: 14.06 | AO33: =AVERAGE(AM33:AN33) -> 14.1 | AV33: =A33 -> PN20 | AW33: =F33 -> 6.9638889 | AX33: 2.2904932 | AZ33: < E-2 | BA33: 56000 | BB33: 3.2233939e+09
A34: PN21 | B34: 43664.792 | C34: =(B34-B33)*24+C33 -> 264.1 | D34: =C34/24 -> 11.004167 | E34: =(B34-$K$7)*24 -> 177.96667 | F34: =E34/24 -> 7.4152778 | I34: 144.75 | J34: 131.95 | K34: 2.47 | L34: 2.61 | M34: =AVERAGE(K34:L34) -> 2.54 | N34: 2.64 | O34: 2.77 | P34: =AVERAGE(N34:O34) -> 2.705 | Q34: =(LN(M34)-LN(M33))/(C34-C33) -> -0.0040874376 | R34: 93.6 | S34: 94.3 | T34: =AVERAGE(R34:S34) -> 93.95 | U34: 16.11 | V34: 16.01 | W34: =AVERAGE(U34:V34) -> 16.06 | AD34: 1.18 | AE34: 1.19 | AF34: =AVERAGE(AD34:AE34) -> 1.185 | AG34: 1.24 | AH34: 1.24 | AI34: =AVERAGE(AG34:AH34) -> 1.24 | AJ34: 95.1 | AK34: 95.6 | AL34: =AVERAGE(AJ34:AK34) -> 95.35 | AM34: 15.67 | AN34: 15.73 | AO34: =AVERAGE(AM34:AN34) -> 15.7 | AV34: =A34 -> PN21 | AW34: =F34 -> 7.4152778 | AX34: 0 | AZ34: 4 | BA34: 10000 | BB34: 2.6164773e+09
A35: PN22 | B35: 43665.33 | C35: =(B35-B34)*24+C34 -> 277.01667 | D35: =C35/24 -> 11.542361 | E35: =(B35-$K$7)*24 -> 190.88333 | F35: =E35/24 -> 7.9534722 | I35: 145.79 | J35: 131.57 | K35: 2.9 | L35: 2.74 | M35: =AVERAGE(K35:L35) -> 2.82 | N35: 3.07 | O35: 2.89 | P35: =AVERAGE(N35:O35) -> 2.98 | Q35: =(LN(M35)-LN(M34))/(C35-C34) -> 0.008095959 | R35: 94.4 | S35: 95 | T35: =AVERAGE(R35:S35) -> 94.7 | U35: 16.11 | V35: 16.21 | W35: =AVERAGE(U35:V35) -> 16.16 | AD35: 1.56 | AE35: 1.64 | AF35: =AVERAGE(AD35:AE35) -> 1.6 | AG35: 1.65 | AH35: 1.72 | AI35: =AVERAGE(AG35:AH35) -> 1.685 | AJ35: 94.8 | AK35: 95.4 | AL35: =AVERAGE(AJ35:AK35) -> 95.1 | AM35: 15.44 | AN35: 15.43 | AO35: =AVERAGE(AM35:AN35) -> 15.435 | AV35: =A35 -> PN22 | AW35: =F35 -> 7.9534722 | AX35: 0 | AZ35: 4 | BA35: 1300 | BB35: 1.0545938e+09
A36: PN23 | B36: 43665.792 | C36: =(B36-B35)*24+C35 -> 288.1 | D36: =C36/24 -> 12.004167 | E36: =(B36-$K$7)*24 -> 201.96667 | F36: =E36/24 -> 8.4152778 | K36: 2.37 | L36: 2.45 | M36: =AVERAGE(K36:L36) -> 2.41 | N36: 2.52 | O36: 2.6 | P36: =AVERAGE(N36:O36) -> 2.56 | Q36: =(LN(M36)-LN(M35))/(C36-C35) -> -0.014175351 | R36: 93.9 | S36: 94.4 | T36: =AVERAGE(R36:S36) -> 94.15 | U36: 16 | V36: 15.96 | W36: =AVERAGE(U36:V36) -> 15.98 | AD36: 2.15 | AE36: 2.22 | AF36: =AVERAGE(AD36:AE36) -> 2.185 | AG36: 2.27 | AH36: 2.32 | AI36: =AVERAGE(AG36:AH36) -> 2.295 | AJ36: 94.5 | AK36: 95.7 | AL36: =AVERAGE(AJ36:AK36) -> 95.1 | AM36: 15.51 | AN36: 15.6 | AO36: =AVERAGE(AM36:AN36) -> 15.555 | AV36: =A36 -> PN23 | AW36: =F36 -> 8.4152778 | AX36: 0 | AZ36: 8 | BA36: 0 | BB36: 3.1920913e+08
A37: PN24 | B37: 43666.34 | C37: =(B37-B36)*24+C36 -> 301.26667 | D37: =C37/24 -> 12.552778 | E37: =(B37-$K$7)*24 -> 215.13333 | F37: =E37/24 -> 8.9638889 | G37: 7.45 | H37: 7.54 | I37: 145.56 | J37: 131.62 | K37: 2.61 | L37: 2.54 | M37: =AVERAGE(K37:L37) -> 2.575 | N37: 2.76 | O37: 2.7 | P37: =AVERAGE(N37:O37) -> 2.73 | Q37: =(LN(M37)-LN(M36))/(C37-C36) -> 0.0050295787 | R37: 94.6 | S37: 93.9 | T37: =AVERAGE(R37:S37) -> 94.25 | U37: 16.12 | V37: 16.09 | W37: =AVERAGE(U37:V37) -> 16.105 | AD37: 2.55 | AE37: 2.36 | AF37: =AVERAGE(AD37:AE37) -> 2.455 | AG37: 2.69 | AH37: 2.48 | AI37: =AVERAGE(AG37:AH37) -> 2.585 | AJ37: 95 | AK37: 95.4 | AL37: =AVERAGE(AJ37:AK37) -> 95.2 | AM37: 15.49 | AN37: 15.58 | AO37: =AVERAGE(AM37:AN37) -> 15.535 | AV37: =A37 -> PN24 | AW37: =F37 -> 8.9638889 | AX37: 0 | AZ37: 620000 | BA37: 3200000 | BB37: 2.3303059e+08
A38: PN25 | B38: 43666.796 | C38: =(B38-B37)*24+C37 -> 312.2 | D38: =C38/24 -> 13.008333 | E38: =(B38-$K$7)*24 -> 226.06667 | F38: =E38/24 -> 9.4194444 | I38: 145.49 | J38: 132.45 | K38: 2.37 | L38: 2.35 | M38: =AVERAGE(K38:L38) -> 2.36 | N38: 2.52 | O38: 2.5 | P38: =AVERAGE(N38:O38) -> 2.51 | Q38: =(LN(M38)-LN(M37))/(C38-C37) -> -0.0079745044 | R38: 94.4 | S38: 94 | T38: =AVERAGE(R38:S38) -> 94.2 | U38: 16.14 | V38: 16.19 | W38: =AVERAGE(U38:V38) -> 16.165 | AD38: 1.24 | AE38: 1.19 | AF38: =AVERAGE(AD38:AE38) -> 1.215 | AG38: 1.35 | AH38: 1.29 | AI38: =AVERAGE(AG38:AH38) -> 1.32 | AJ38: 92.2 | AK38: 92.3 | AL38: =AVERAGE(AJ38:AK38) -> 92.25 | AM38: 13.65 | AN38: 13.55 | AO38: =AVERAGE(AM38:AN38) -> 13.6 | AV38: =A38 -> PN25 | AW38: =F38 -> 9.4194444 | AX38: 2.8220471 | AZ38: 48000000 | BA38: 43000000 | BB38: 6.0219071e+10
A39: PN26 | B39: 43667.343 | C39: =(B39-B38)*24+C38 -> 325.33333 | D39: =C39/24 -> 13.555556 | E39: =(B39-$K$7)*24 -> 239.2 | F39: =E39/24 -> 9.9666667 | G39: 7.48 | H39: 7.48 | I39: 145.66 | J39: 132 | K39: 2.46 | L39: 2.46 | M39: =AVERAGE(K39:L39) -> 2.46 | N39: 2.63 | O39: 2.63 | P39: =AVERAGE(N39:O39) -> 2.63 | Q39: =(LN(M39)-LN(M38))/(C39-C38) -> 0.003159878 | R39: 93.6 | S39: 93.4 | T39: =AVERAGE(R39:S39) -> 93.5 | U39: 16.13 | V39: 16.15 | W39: =AVERAGE(U39:V39) -> 16.14 | AD39: 0.33 | AE39: 0.35 | AF39: =AVERAGE(AD39:AE39) -> 0.34 | AG39: 0.39 | AH39: 0.4 | AI39: =AVERAGE(AG39:AH39) -> 0.395 | AJ39: 84.5 | AK39: 86.7 | AL39: =AVERAGE(AJ39:AK39) -> 85.6 | AM39: 12.86 | AN39: 12.83 | AO39: =AVERAGE(AM39:AN39) -> 12.845 | AV39: =A39 -> PN26 | AW39: =F39 -> 9.9666667 | AX39: 2.6508736 | AZ39: 480000 | BA39: 4300000 | BB39: 2.3594893e+10
A40: PN27 | B40: 43667.803 | C40: =(B40-B39)*24+C39 -> 336.38333 | D40: =C40/24 -> 14.015972 | E40: =(B40-$K$7)*24 -> 250.25 | F40: =E40/24 -> 10.427083 | I40: 146.39 | J40: 132.17 | K40: 2.19 | L40: 2.15 | M40: =AVERAGE(K40:L40) -> 2.17 | N40: 2.34 | O40: 2.29 | P40: =AVERAGE(N40:O40) -> 2.315 | Q40: =(LN(M40)-LN(M39))/(C40-C39) -> -0.01135151 | R40: 93.9 | S40: 93.7 | T40: =AVERAGE(R40:S40) -> 93.8 | U40: 16.45 | V40: 16.55 | W40: =AVERAGE(U40:V40) -> 16.5 | AD40: 0.77 | AE40: 0.73 | AF40: =AVERAGE(AD40:AE40) -> 0.75 | AG40: 0.81 | AH40: 0.77 | AI40: =AVERAGE(AG40:AH40) -> 0.79 | AJ40: 94.8 | AK40: 95.3 | AL40: =AVERAGE(AJ40:AK40) -> 95.05 | AM40: 14.28 | AN40: 14.39 | AO40: =AVERAGE(AM40:AN40) -> 14.335 | AV40: =A40 -> PN27 | AW40: =F40 -> 10.427083 | AX40: 2.3978581 | AZ40: 2000 | BA40: 3200000 | BB40: 1.5436689e+10
A41: PN28 | B41: 43668.338 | C41: =(B41-B40)*24+C40 -> 349.21667 | D41: =C41/24 -> 14.550694 | E41: =(B41-$K$7)*24 -> 263.08333 | F41: =E41/24 -> 10.961806 | G41: 7.49 | H41: 7.53 | I41: 145.51 | J41: 131.51 | K41: 2.48 | L41: 2.52 | M41: =AVERAGE(K41:L41) -> 2.5 | N41: 2.66 | O41: 2.7 | P41: =AVERAGE(N41:O41) -> 2.68 | Q41: =(LN(M41)-LN(M40))/(C41-C40) -> 0.011030927 | R41: 93.3 | S41: 93.3 | T41: =AVERAGE(R41:S41) -> 93.3 | U41: 15.91 | V41: 15.93 | W41: =AVERAGE(U41:V41) -> 15.92 | AD41: 0.57 | AE41: 0.61 | AF41: =AVERAGE(AD41:AE41) -> 0.59 | AG41: 0.62 | AH41: 0.65 | AI41: =AVERAGE(AG41:AH41) -> 0.635 | AJ41: 92.3 | AK41: 92.5 | AL41: =AVERAGE(AJ41:AK41) -> 92.4 | AM41: 14.18 | AN41: 15 | AO41: =AVERAGE(AM41:AN41) -> 14.59 | AV41: =A41 -> PN28 | AW41: =F41 -> 10.961806 | AX41: 2.2641629 | AZ41: 800 | BA41: 430000 | BB41: 7.0166606e+09
A42: PN29 | B42: 43668.797 | C42: =(B42-B41)*24+C41 -> 360.21667 | D42: =C42/24 -> 15.009028 | E42: =(B42-$K$7)*24 -> 274.08333 | F42: =E42/24 -> 11.420139 | I42: 145.63 | J42: 132.05 | K42: 2.37 | L42: 2.36 | M42: =AVERAGE(K42:L42) -> 2.365 | N42: 2.52 | O42: 2.5 | P42: =AVERAGE(N42:O42) -> 2.51 | Q42: =(LN(M42)-LN(M41))/(C42-C41) -> -0.00504661 | R42: 94.2 | S42: 94.3 | T42: =AVERAGE(R42:S42) -> 94.25 | U42: 16.16 | V42: 16.23 | W42: =AVERAGE(U42:V42) -> 16.195 | AD42: 0.88 | AE42: 0.92 | AF42: =AVERAGE(AD42:AE42) -> 0.9 | AG42: 0.93 | AH42: 0.97 | AI42: =AVERAGE(AG42:AH42) -> 0.95 | AJ42: 94.2 | AK42: 94.9 | AL42: =AVERAGE(AJ42:AK42) -> 94.55 | AM42: 15.24 | AN42: 15.36 | AO42: =AVERAGE(AM42:AN42) -> 15.3 | AV42: =A42 -> PN29 | AW42: =F42 -> 11.420139 | AX42: 2.0402413 | AZ42: 120 | BA42: 130000 | BB42: 3.5088609e+09
A43: PN30 | B43: 43669.347 | C43: =(B43-B42)*24+C42 -> 373.41667 | D43: =C43/24 -> 15.559028 | E43: =(B43-$K$7)*24 -> 287.28333 | F43: =E43/24 -> 11.970139 | G43: 7.51 | H43: 7.53 | I43: 147.21 | J43: 132.27 | K43: 2.48 | L43: 2.45 | M43: =AVERAGE(K43:L43) -> 2.465 | N43: 2.65 | O43: 2.61 | P43: =AVERAGE(N43:O43) -> 2.63 | Q43: =(LN(M43)-LN(M42))/(C43-C42) -> 0.003137408 | R43: 93.6 | S43: 94.2 | T43: =AVERAGE(R43:S43) -> 93.9 | U43: 15.91 | V43: 15.88 | W43: =AVERAGE(U43:V43) -> 15.895 | AD43: 1.07 | AE43: 1.04 | AF43: =AVERAGE(AD43:AE43) -> 1.055 | AG43: 1.12 | AH43: 1.11 | AI43: =AVERAGE(AG43:AH43) -> 1.115 | AJ43: 95.2 | AK43: 93.7 | AL43: =AVERAGE(AJ43:AK43) -> 94.45 | AM43: 15.18 | AN43: 15.24 | AO43: =AVERAGE(AM43:AN43) -> 15.21 | AV43: =A43 -> PN30 | AW43: =F43 -> 11.970139 | AX43: 0 | AZ43: 12 | BA43: 24000 | BB43: 2.4378464e+09
A44: PN31 | B44: 43669.808 | C44: =(B44-B43)*24+C43 -> 384.48333 | D44: =C44/24 -> 16.020139 | E44: =(B44-$K$7)*24 -> 298.35 | F44: =E44/24 -> 12.43125 | I44: 145.97 | J44: 131.11 | K44: 2.38 | L44: 2.36 | M44: =AVERAGE(K44:L44) -> 2.37 | N44: 2.55 | O44: 2.47 | P44: =AVERAGE(N44:O44) -> 2.51 | Q44: =(LN(M44)-LN(M43))/(C44-C43) -> -0.0035513722 | R44: 93.5 | S44: 95.5 | T44: =AVERAGE(R44:S44) -> 94.5 | U44: 16.42 | V44: 16.47 | W44: =AVERAGE(U44:V44) -> 16.445 | AD44: 1.59 | AE44: 1.55 | AF44: =AVERAGE(AD44:AE44) -> 1.57 | AG44: 1.7 | AH44: 1.64 | AI44: =AVERAGE(AG44:AH44) -> 1.67 | AJ44: 93.6 | AK44: 94.8 | AL44: =AVERAGE(AJ44:AK44) -> 94.2 | AM44: 15.74 | AN44: 15.98 | AO44: =AVERAGE(AM44:AN44) -> 15.86 | AV44: =A44 -> PN31 | AW44: =F44 -> 12.43125 | AX44: 0 | AZ44: 4 | BA44: 1300 | BB44: 6.474135e+08
...

Sheet Cells
C2: CELL BIOREACTOR | K2: Virus Bioreactor 1 22h

Sheet MOI

Sheet Virus

Sheet Estimates
A2: Semi-continuous two-stage cultivation
F8: Duplicate 1 | I8: Cell Shaker
F9: V4 | G9: V2 | H9: V3 | I9: V1
A10: # Sample | B10: Time | C10: Time | E10: Time | F10: Harvest Vol | G10: Transfer from CB to VB | H10: Fresh Med. to VB | I10: Fresh Med. to CB
B11: (d.m.y h:m) | C11: (h) | E11: (d p.i) | F11: mL | G11: mL | H11: mL | I11: mL
A12: PN0 | B12: ='General Parameters'!B13 -> 43653.787
A13: PN1 | B13: ='General Parameters'!B14 -> 43654.802 | C13: 12 | F13: =(C13-C12)*60*$L$31 -> 42.282 | G13: =(C13-C12)*60*$L$29 -> 28.188 | H13: =(C13-C12)*60*$L$30 -> 14.094 | I13: =G13 -> 28.188
A14: PN2 | B14: ='General Parameters'!B15 -> 43655.349 | C14: 0 | F14: =(C14-C13)*60*$L$31 -> -42.282 | G14: =(C14-C13)*60*$L$29 -> -28.188 | H14: =(C14-C13)*60*$L$30 -> -14.094 | I14: =G14 -> -28.188 | K14: Specific growth rate (used for calculations)
A15: PN3 | B15: ='General Parameters'!B16 -> 43655.812 | C15: 12 | F15: =(C15-C14)*60*$L$31 -> 42.282 | G15: =(C15-C14)*60*$L$29 -> 28.188 | H15: =(C15-C14)*60*$L$30 -> 14.094 | I15: =G15 -> 28.188 | K15: 0.029 | L15: (h-1)
A16: PN4 | B16: ='General Parameters'!B17 -> 43656.36 | C16: =(B16-B15)*24+C15 -> 25.15 | F16: =(C16-C15)*60*$L$31 -> 46.334025 | G16: =(C16-C15)*60*$L$29 -> 30.88935 | H16: =(C16-C15)*60*$L$30 -> 15.444675 | I16: =G16 -> 30.88935
A17: PN5 | B17: ='General Parameters'!B18 -> 43656.878 | C17: =(B17-B16)*24+C16 -> 37.566667 | F17: =(C17-C16)*60*$L$31 -> 43.750125 | G17: =(C17-C16)*60*$L$29 -> 29.16675 | H17: =(C17-C16)*60*$L$30 -> 14.583375 | I17: =G17 -> 29.16675
A18: PN6 | B18: ='General Parameters'!B19 -> 43657.361 | C18: =(B18-B17)*24+C17 -> 49.166667 | F18: =(C18-C17)*60*$L$31 -> 40.8726 | G18: =(C18-C17)*60*$L$29 -> 27.2484 | H18: =(C18-C17)*60*$L$30 -> 13.6242 | I18: =G18 -> 27.2484
A19: PN7 | B19: ='General Parameters'!B20 -> 43657.873 | C19: =(B19-B18)*24+C18 -> 61.45 | F19: =(C19-C18)*60*$L$31 -> 43.280325 | G19: =(C19-C18)*60*$L$29 -> 28.85355 | H19: =(C19-C18)*60*$L$30 -> 14.426775 | I19: =G19 -> 28.85355
A20: PN8 | B20: ='General Parameters'!B21 -> 43658.365 | C20: =(B20-B19)*24+C19 -> 73.266667 | F20: =(C20-C19)*60*$L$31 -> 41.636025 | G20: =(C20-C19)*60*$L$29 -> 27.75735 | H20: =(C20-C19)*60*$L$30 -> 13.878675 | I20: =G20 -> 27.75735 | K20: RT CB | L20: =1/(L21*60) -> 38.314176
A21: PN9 | B21: ='General Parameters'!B22 -> 43658.773 | C21: =(B21-B20)*24+C20 -> 83.05 | F21: =(C21-C20)*60*$L$31 -> 34.471575 | G21: =(C21-C20)*60*$L$29 -> 22.98105 | H21: =(C21-C20)*60*$L$30 -> 11.490525 | I21: =G21 -> 22.98105 | K21: Dilution rate CB | L21: =0.9*K15/60 -> 0.000435 | M21: min-1
A22: PN10 | B22: ='General Parameters'!B23 -> 43659.397 | C22: =(B22-B21)*24+C21 -> 98.016667 | F22: =(C22-C21)*60*$L$31 -> 52.73505 | G22: =(C22-C21)*60*$L$29 -> 35.1567 | H22: =(C22-C21)*60*$L$30 -> 17.57835 | I22: =G22 -> 35.1567 | K22: Dilution rate VB
A23: PN11 | B23: ='General Parameters'!B24 -> 43659.87 | C23: =(B23-B22)*24+C22 -> 109.38333 | F23: =(C23-C22)*60*$L$31 -> 40.05045 | G23: =(C23-C22)*60*$L$29 -> 26.7003 | H23: =(C23-C22)*60*$L$30 -> 13.35015 | I23: =G23 -> 26.7003 | K23: =R24 -> 0.00075757576 | L23: min-1 | O23: =L26/L31/60 -> 22 | Q23: Verweilzeit | R23: 22 | S23: h
A24: PN12 | B24: ='General Parameters'!B25 -> 43660.329 | C24: =(B24-B23)*24+C23 -> 120.4 | F24: =(C24-C23)*60*$L$31 -> 38.817225 | G24: =(C24-C23)*60*$L$29 -> 25.87815 | H24: =(C24-C23)*60*$L$30 -> 12.939075 | I24: =G24 -> 25.87815 | Q24: D | R24: =1/R23/60 -> 0.00075757576 | S24: min-1
A25: PN13 | B25: ='General Parameters'!B26 -> 43660.836 | C25: =(B25-B24)*24+C24 -> 132.56667 | F25: =(C25-C24)*60*$L$31 -> 42.86925 | G25: =(C25-C24)*60*$L$29 -> 28.5795 | H25: =(C25-C24)*60*$L$30 -> 14.28975 | I25: =G25 -> 28.5795 | K25: Volume CB | L25: 90 | M25: mL | Q25: V | R25: =L31/R24 -> 77.517 | S25: ml
A26: PN14 | B26: ='General Parameters'!B27 -> 43661.38 | C26: =(B26-B25)*24+C25 -> 145.61667 | F26: =(C26-C25)*60*$L$31 -> 45.981675 | G26: =(C26-C25)*60*$L$29 -> 30.65445 | H26: =(C26-C25)*60*$L$30 -> 15.327225 | I26: =G26 -> 30.65445 | K26: Volume VB | L26: =L31/K23 -> 77.517 | M26: mL
A27: PN15 | B27: ='General Parameters'!B28 -> 43661.847 | C27: =(B27-B26)*24+C26 -> 156.81667 | F27: =(C27-C26)*60*$L$31 -> 39.4632 | G27: =(C27-C26)*60*$L$29 -> 26.3088 | H27: =(C27-C26)*60*$L$30 -> 13.1544 | I27: =G27 -> 26.3088
A28: PN16 | B28: ='General Parameters'!B29 -> 43662.381 | C28: =(B28-B27)*24+C27 -> 169.65 | F28: =(C28-C27)*60*$L$31 -> 45.21825 | G28: =(C28-C27)*60*$L$29 -> 30.1455 | H28: =(C28-C27)*60*$L$30 -> 15.07275 | I28: =G28 -> 30.1455 | K28: Flow 1 | L28: =L21*L25 -> 0.03915 | M28: mL/min
A29: PN17 | B29: ='General Parameters'!B30 -> 43662.852 | C29: =(B29-B28)*24+C28 -> 180.95 | F29: =(C29-C28)*60*$L$31 -> 39.81555 | G29: =(C29-C28)*60*$L$29 -> 26.5437 | H29: =(C29-C28)*60*$L$30 -> 13.27185 | I29: =G29 -> 26.5437 | K29: Flow 2 | L29: =L28 -> 0.03915 | M29: mL/min
A30: PN18 | B30: ='General Parameters'!B31 -> 43663.369 | C30: =(B30-B29)*24+C29 -> 193.36667 | F30: =(C30-C29)*60*$L$31 -> 43.750125 | G30: =(C30-C29)*60*$L$29 -> 29.16675 | H30: =(C30-C29)*60*$L$30 -> 14.583375 | I30: =G30 -> 29.16675 | K30: Flow 3 | L30: =0.5*L29 -> 0.019575 | M30: mL/min | N30: (coming from a mass balance considering that dilution rate of the overall process is equal to dilution rate of CB
A31: PN19 | B31: ='General Parameters'!B32 -> 43663.866 | C31: =(B31-B30)*24+C30 -> 205.28333 | F31: =(C31-C30)*60*$L$31 -> 41.988375 | G31: =(C31-C30)*60*$L$29 -> 27.99225 | H31: =(C31-C30)*60*$L$30 -> 13.996125 | I31: =G31 -> 27.99225 | K31: Flow 4 | L31: =L30+L28 -> 0.058725 | M31: mL/min
A32: PN20 | B32: ='General Parameters'!B33 -> 43664.34 | C32: =(B32-B31)*24+C31 -> 216.66667 | F32: =(C32-C31)*60*$L$31 -> 40.109175 | G32: =(C32-C31)*60*$L$29 -> 26.73945 | H32: =(C32-C31)*60*$L$30 -> 13.369725 | I32: =G32 -> 26.73945
A33: PN21 | B33: ='General Parameters'!B34 -> 43664.792 | C33: =(B33-B32)*24+C32 -> 227.5 | F33: =(C33-C32)*60*$L$31 -> 38.17125 | G33: =(C33-C32)*60*$L$29 -> 25.4475 | H33: =(C33-C32)*60*$L$30 -> 12.72375 | I33: =G33 -> 25.4475 | O33: =L30/L29 -> 0.5
A34: PN22 | B34: ='General Parameters'!B35 -> 43665.33 | C34: =(B34-B33)*24+C33 -> 240.41667 | F34: =(C34-C33)*60*$L$31 -> 45.511875 | G34: =(C34-C33)*60*$L$29 -> 30.34125 | H34: =(C34-C33)*60*$L$30 -> 15.170625 | I34: =G34 -> 30.34125
A35: PN23 | B35: ='General Parameters'!B36 -> 43665.792 | C35: =(B35-B34)*24+C34 -> 251.5 | F35: =(C35-C34)*60*$L$31 -> 39.052125 | G35: =(C35-C34)*60*$L$29 -> 26.03475 | H35: =(C35-C34)*60*$L$30 -> 13.017375 | I35: =G35 -> 26.03475 | K35: Infection
A36: PN24 | B36: ='General Parameters'!B37 -> 43666.34 | C36: =(B36-B35)*24+C35 -> 264.66667 | F36: =(C36-C35)*60*$L$31 -> 46.39275 | G36: =(C36-C35)*60*$L$29 -> 30.9285 | H36: =(C36-C35)*60*$L$30 -> 15.46425 | I36: =G36 -> 30.9285 | K36: MOI E-1
A37: PN25 | B37: ='General Parameters'!B38 -> 43666.796 | C37: =(B37-B36)*24+C36 -> 275.6 | F37: =(C37-C36)*60*$L$31 -> 38.5236 | G37: =(C37-C36)*60*$L$29 -> 25.6824 | H37: =(C37-C36)*60*$L$30 -> 12.8412 | I37: =G37 -> 25.6824
A38: PN26 | B38: ='General Parameters'!B39 -> 43667.343 | C38: =(B38-B37)*24+C37 -> 288.73333 | F38: =(C38-C37)*60*$L$31 -> 46.2753 | G38: =(C38-C37)*60*$L$29 -> 30.8502 | H38: =(C38-C37)*60*$L$30 -> 15.4251 | I38: =G38 -> 30.8502
A39: PN27 | B39: ='General Parameters'!B40 -> 43667.803 | C39: =(B39-B38)*24+C38 -> 299.78333 | F39: =(C39-C38)*60*$L$31 -> 38.934675 | G39: =(C39-C38)*60*$L$29 -> 25.95645 | H39: =(C39-C38)*60*$L$30 -> 12.978225 | I39: =G39 -> 25.95645
A40: PN28 | B40: ='General Parameters'!B41 -> 43668.338 | C40: =(B40-B39)*24+C39 -> 312.61667 | F40: =(C40-C39)*60*$L$31 -> 45.21825 | G40: =(C40-C39)*60*$L$29 -> 30.1455 | H40: =(C40-C39)*60*$L$30 -> 15.07275 | I40: =G40 -> 30.1455
A41: PN29 | B41: ='General Parameters'!B42 -> 43668.797 | C41: =(B41-B40)*24+C40 -> 323.61667 | F41: =(C41-C40)*60*$L$31 -> 38.7585 | G41: =(C41-C40)*60*$L$29 -> 25.839 | H41: =(C41-C40)*60*$L$30 -> 12.9195 | I41: =G41 -> 25.839
A42: PN30 | B42: ='General Parameters'!B43 -> 43669.347 | C42: =(B42-B41)*24+C41 -> 336.81667 | F42: =(C42-C41)*60*$L$31 -> 46.5102 | G42: =(C42-C41)*60*$L$29 -> 31.0068 | H42: =(C42-C41)*60*$L$30 -> 15.5034 | I42: =G42 -> 31.0068
A43: PN31 | B43: ='General Parameters'!B44 -> 43669.808 | C43: =(B43-B42)*24+C42 -> 347.88333 | F43: =(C43-C42)*60*$L$31 -> 38.9934 | G43: =(C43-C42)*60*$L$29 -> 25.9956 | H43: =(C43-C42)*60*$L$30 -> 12.9978 | I43: =G43 -> 25.9956
A44: PN32 | B44: ='General Parameters'!B45 -> 43670.349 | C44: =(B44-B43)*24+C43 -> 360.88333 | F44: =(C44-C43)*60*$L$31 -> 45.8055 | G44: =(C44-C43)*60*$L$29 -> 30.537 | H44: =(C44-C43)*60*$L$30 -> 15.2685 | I44: =G44 -> 30.537
A45: PN33 | B45: ='General Parameters'!B46 -> 43670.877 | C45: =(B45-B44)*24+C44 -> 373.55 | F45: =(C45-C44)*60*$L$31 -> 44.631 | G45: =(C45-C44)*60*$L$29 -> 29.754 | H45: =(C45-C44)*60*$L$30 -> 14.877 | I45: =G45 -> 29.754
A46: PN34 | B46: ='General Parameters'!B47 -> 43671.364 | C46: =(B46-B45)*24+C45 -> 385.23333 | F46: =(C46-C45)*60*$L$31 -> 41.166225 | G46: =(C46-C45)*60*$L$29 -> 27.44415 | H46: =(C46-C45)*60*$L$30 -> 13.722075 | I46: =G46 -> 27.44415
...
